Workbook

Sheet Bonaship Model
B2: BONASHIP — Kalkulačka spolufinancovania
B3: Modré hodnoty sú vstupné parametre — môžete ich meniť
B5: PARAMETRE NEHNUTEĽNOSTI
B6: Hodnota nehnuteľnosti | C6: 180000 | D6: Odhadovaná trhová cena
B7: Vlastné zdroje | C7: 18000 | D7: Hotovosť / úspory zákazníka
B8: Suma od Bonaship | C8: 18000 | D8: Spolufinancovanie (max 15% hodnoty)
B9: Horizont vysporiadania (roky) | C9: 7 | D9: Kedy plánujete predať / refinancovať
B10: Očakávané zhodnotenie p.a. | C10: 0.0391 | D10: SK priemer podľa NBS: 3.91% p.a.
B12: BONASHIP PODMIENKY (UPRAVITEĽNÉ)
B13: Podiel z predajnej ceny: 1–3 roky | C13: 0.15
B14: Podiel z predajnej ceny: 4–6 rokov | C14: 0.175
B15: Podiel z predajnej ceny: 7–10 rokov | C15: 0.2
B16: Poznámka: podiel sa počíta z CELEJ predajnej ceny
B17: Jednorazový poplatok (% z investície) | C17: 0.05
B18: Max. poplatok | C18: 20000
B20: VÝPOČET BONASHIP
B21: Budúca hodnota nehnuteľnosti | C21: =C6*(1+C10)^C9
B22: Zhodnotenie (pre info) | C22: =C21-C6
B23: Aplikovaný podiel | C23: =IF(C9<=3,C13,IF(C9<=6,C14,C15))
B24: Investor payout (% z predajnej ceny) | C24: =C21*C23
B25: Jednorazový poplatok | C25: =MIN(C8*C17,C18)
B26: Náklad zákazníka (bez poplatku) | C26: =C24-C8
B27: Celkový investor payout | C27: =C24
B28: Celkový náklad zákazníka | C28: =C25+C24-C8
B29: Zákazník zaplatí investorovi celkom | C29: =C25+C24
B30: Zhodnotenie zákazníka (zostatok) | C30: =C22-(C24-C8)
B31: Mesačná splátka Bonaship | C31: 0
B32: IRR investora (ročný výnos, zložený) | C32: =IFERROR((C24/C8)^(1/C9)-1, 0)
B33: SCENÁRE ZHODNOTENIA
C34: Konzervatívny (1%) | D34: Stredný (3%) | E34: Optimistický (5%)
B35: Ročné zhodnotenie | C35: 0.01 | D35: 0.03 | E35: 0.05
B36: Budúca hodnota bytu | C36: =C6*(1+C35)^C9 | D36: =C6*(1+D35)^C9 | E36: =C6*(1+E35)^C9
B37: Zhodnotenie | C37: =C36-C6 | D37: =D36-C6 | E37: =E36-C6
B38: Podiel investora | C38: =C36*C23 | D38: =D36*C23 | E38: =E36*C23
B39: Náklad zákazníka celkom | C39: =C25+C38-C8 | D39: =C25+D38-C8 | E39: =C25+E38-C8
B40: Zhodnotenie zákazníka | C40: =C37-(C38-C8) | D40: =D37-(D38-C8) | E40: =E37-(E38-C8)
B41: IRR investora p.a. | C41: =IFERROR((C38/C8)^(1/C9)-1,0) | D41: =IFERROR((D38/C8)^(1/C9)-1,0) | E41: =IFERROR((E38/C8)^(1/C9)-1,0)
B44: HYPOTÉKA ZÁKAZNÍKA (VSTUP PRE REFINANCOVANIE)
B45: Suma hypotéky zákazníka | C45: =C6-C7-C8 | D45: Hodnota − vlastné zdroje − Bonaship
B46: Úroková sadzba hypotéky p.a. | C46: 0.025 | D46: Zadajte reálnu sadzbu (napr. 0.025 = 2.5%)
...

Sheet Porovnanie s úvermi
B2: POROVNANIE — Bonaship vs. Spotrebné úvery
B3: Suma zákazníka (auto z Model sheetu): | C3: ='Bonaship Model'!C8 | D3: ← automaticky z Model sheetu, meňte tam
B5: SPLATNOSŤ: 3 ROKOV
B6: Poskytovateľ | C6: Produkt | D6: Typ | E6: Úrok p.a. | F6: Poplatok | G6: Splátka/mes — zákazník | H6: Zákazník zaplatí celkom | I6: Náklad zákazníka | J6: V registri
B7: Slovenská sporiteľňa | C7: Spotrebný úver | D7: Banka | E7: 0.0699 | F7: 0 | G7: =308.73*$C$3/10000 | H7: =11114.11*$C$3/10000 | I7: =1114.11*$C$3/10000 | J7: ÁNO
B8: Prima banka | C8: Pôžička | D8: Banka | E8: 0.059 | F8: 0.05 | G8: =303.77*$C$3/10000 | H8: =11435.59*$C$3/10000 | I8: =1435.59*$C$3/10000 | J8: ÁNO
B9: Tatra banka | C9: Bezúčelový úver | D9: Banka | E9: 0.0649 | F9: 0.02 | G9: =306.44*$C$3/10000 | H9: =11232*$C$3/10000 | I9: =1232*$C$3/10000 | J9: ÁNO
B10: 365.bank | C10: Pôžička od 365 | D10: Banka | E10: 0.06 | F10: 0.02 | G10: =304.22*$C$3/10000 | H10: =11151.9*$C$3/10000 | I10: =1151.9*$C$3/10000 | J10: ÁNO
B11: mBank | C11: mPôžička Plus | D11: Banka | E11: 0.0689 | F11: 0.015 | G11: =308.27*$C$3/10000 | H11: =11247.66*$C$3/10000 | I11: =1247.66*$C$3/10000 | J11: ÁNO
B12: Cetelem | C12: Cetelem pôžička | D12: Nebankovka | E12: 0.049 | F12: 0 | G12: =299.26*$C$3/10000 | H12: =10773.37*$C$3/10000 | I12: =773.37*$C$3/10000 | J12: ÁNO
B13: Home Credit | C13: Online pôžička | D13: Nebankovka | E13: 0.19 | F13: 0 | G13: =366.56*$C$3/10000 | H13: =13196.17*$C$3/10000 | I13: =3196.17*$C$3/10000 | J13: ÁNO
B14: 🟢 Bonaship | C14: Spolufinancovanie | D14: Investor | E14: — | F14: — | G14: 0 | H14: =('Bonaship Model'!C6*(1+'Bonaship Model'!C10)^3)*'Bonaship Model'!C13+MIN('Bonaship Model'!C8*'Bonaship Model'!C17,'Bonaship Model'!C18) | I14: =('Bonaship Model'!C6*(1+'Bonaship Model'!C10)^3)*'Bonaship Model'!C13+MIN('Bonaship Model'!C8*'Bonaship Model'!C17,'Bonaship Model'!C18)-'Bonaship Model'!C8 | J14: NIE
B16: SPLATNOSŤ: 5 ROKOV
B17: Poskytovateľ | C17: Produkt | D17: Typ | E17: Úrok p.a. | F17: Poplatok | G17: Splátka/mes — zákazník | H17: Zákazník zaplatí celkom | I17: Náklad zákazníka | J17: V registri
B18: Slovenská sporiteľňa | C18: Spotrebný úver | D18: Banka | E18: 0.0699 | F18: 0 | G18: =197.96*$C$3/10000 | H18: =11877.89*$C$3/10000 | I18: =1877.89*$C$3/10000 | J18: ÁNO
B19: Prima banka | C19: Pôžička | D19: Banka | E19: 0.059 | F19: 0.05 | G19: =192.86*$C$3/10000 | H19: =12071.8*$C$3/10000 | I19: =2071.8*$C$3/10000 | J19: ÁNO
B20: Tatra banka | C20: Bezúčelový úver | D20: Banka | E20: 0.0649 | F20: 0.02 | G20: =195.61*$C$3/10000 | H20: =11936.88*$C$3/10000 | I20: =1936.88*$C$3/10000 | J20: ÁNO
B21: 365.bank | C21: Pôžička od 365 | D21: Banka | E21: 0.06 | F21: 0.02 | G21: =193.33*$C$3/10000 | H21: =11799.68*$C$3/10000 | I21: =1799.68*$C$3/10000 | J21: ÁNO
B22: mBank | C22: mPôžička Plus | D22: Banka | E22: 0.0689 | F22: 0.015 | G22: =197.49*$C$3/10000 | H22: =11999.6*$C$3/10000 | I22: =1999.6*$C$3/10000 | J22: ÁNO
B23: Cetelem | C23: Cetelem pôžička | D23: Nebankovka | E23: 0.049 | F23: 0 | G23: =188.25*$C$3/10000 | H23: =11295.27*$C$3/10000 | I23: =1295.27*$C$3/10000 | J23: ÁNO
B24: Home Credit | C24: Online pôžička | D24: Nebankovka | E24: 0.19 | F24: 0 | G24: =259.41*$C$3/10000 | H24: =15564.33*$C$3/10000 | I24: =5564.33*$C$3/10000 | J24: ÁNO
B25: 🟢 Bonaship | C25: Spolufinancovanie | D25: Investor | E25: — | F25: — | G25: 0 | H25: =('Bonaship Model'!C6*(1+'Bonaship Model'!C10)^5)*'Bonaship Model'!C14+MIN('Bonaship Model'!C8*'Bonaship Model'!C17,'Bonaship Model'!C18) | I25: =('Bonaship Model'!C6*(1+'Bonaship Model'!C10)^5)*'Bonaship Model'!C14+MIN('Bonaship Model'!C8*'Bonaship Model'!C17,'Bonaship Model'!C18)-'Bonaship Model'!C8 | J25: NIE
B27: SPLATNOSŤ: 7 ROKOV
B28: Poskytovateľ | C28: Produkt | D28: Typ | E28: Úrok p.a. | F28: Poplatok | G28: Splátka/mes — zákazník | H28: Zákazník zaplatí celkom | I28: Náklad zákazníka | J28: V registri
B29: Slovenská sporiteľňa | C29: Spotrebný úver | D29: Banka | E29: 0.0699 | F29: 0 | G29: =150.88*$C$3/10000 | H29: =12673.75*$C$3/10000 | I29: =2673.75*$C$3/10000 | J29: ÁNO
B30: Prima banka | C30: Pôžička | D30: Banka | E30: 0.059 | F30: 0.05 | G30: =145.61*$C$3/10000 | H30: =12730.96*$C$3/10000 | I30: =2730.96*$C$3/10000 | J30: ÁNO
B31: Tatra banka | C31: Bezúčelový úver | D31: Banka | E31: 0.0649 | F31: 0.02 | G31: =148.45*$C$3/10000 | H31: =12669.46*$C$3/10000 | I31: =2669.46*$C$3/10000 | J31: ÁNO
B32: 365.bank | C32: Pôžička od 365 | D32: Banka | E32: 0.06 | F32: 0.02 | G32: =146.09*$C$3/10000 | H32: =12471.19*$C$3/10000 | I32: =2471.19*$C$3/10000 | J32: ÁNO
B33: mBank | C33: mPôžička Plus | D33: Banka | E33: 0.0689 | F33: 0.015 | G33: =150.39*$C$3/10000 | H33: =12782.73*$C$3/10000 | I33: =2782.73*$C$3/10000 | J33: ÁNO
B34: Cetelem | C34: Cetelem pôžička | D34: Nebankovka | E34: 0.049 | F34: 0 | G34: =140.87*$C$3/10000 | H34: =11833.05*$C$3/10000 | I34: =1833.05*$C$3/10000 | J34: ÁNO
B35: Home Credit | C35: Online pôžička | D35: Nebankovka | E35: 0.19 | F35: 0 | G35: =216.08*$C$3/10000 | H35: =18150.74*$C$3/10000 | I35: =8150.74*$C$3/10000 | J35: ÁNO
B36: 🟢 Bonaship | C36: Spolufinancovanie | D36: Investor | E36: — | F36: — | G36: 0 | H36: =('Bonaship Model'!C6*(1+'Bonaship Model'!C10)^7)*'Bonaship Model'!C15+MIN('Bonaship Model'!C8*'Bonaship Model'!C17,'Bonaship Model'!C18) | I36: =('Bonaship Model'!C6*(1+'Bonaship Model'!C10)^7)*'Bonaship Model'!C15+MIN('Bonaship Model'!C8*'Bonaship Model'!C17,'Bonaship Model'!C18)-'Bonaship Model'!C8 | J36: NIE
B38: SPLATNOSŤ: 10 ROKOV
B39: Poskytovateľ | C39: Produkt | D39: Typ | E39: Úrok p.a. | F39: Poplatok | G39: Splátka/mes — zákazník | H39: Zákazník zaplatí celkom | I39: Náklad zákazníka | J39: V registri
B40: Slovenská sporiteľňa | C40: Spotrebný úver | D40: Banka | E40: 0.0699 | F40: 0 | G40: =116.06*$C$3/10000 | H40: =13926.83*$C$3/10000 | I40: =3926.83*$C$3/10000 | J40: ÁNO
B41: Prima banka | C41: Pôžička | D41: Banka | E41: 0.059 | F41: 0.05 | G41: =110.52*$C$3/10000 | H41: =13762.28*$C$3/10000 | I41: =3762.28*$C$3/10000 | J41: ÁNO
B42: Tatra banka | C42: Bezúčelový úver | D42: Banka | E42: 0.0649 | F42: 0.02 | G42: =113.5*$C$3/10000 | H42: =13819.65*$C$3/10000 | I42: =3819.65*$C$3/10000 | J42: ÁNO
B43: 365.bank | C43: Pôžička od 365 | D43: Banka | E43: 0.06 | F43: 0.02 | G43: =111.02*$C$3/10000 | H43: =13522.46*$C$3/10000 | I43: =3522.46*$C$3/10000 | J43: ÁNO
B44: mBank | C44: mPôžička Plus | D44: Banka | E44: 0.0689 | F44: 0.015 | G44: =115.54*$C$3/10000 | H44: =14015.08*$C$3/10000 | I44: =4015.08*$C$3/10000 | J44: ÁNO
B45: Cetelem | C45: Cetelem pôžička | D45: Nebankovka | E45: 0.049 | F45: 0 | G45: =105.58*$C$3/10000 | H45: =12669.29*$C$3/10000 | I45: =2669.29*$C$3/10000 | J45: ÁNO
...

Sheet Výhody Bonaship
B2: PREČO BONASHIP? — Výhody pre zákazníka
B3: Požadovaná suma: | C3: ='Bonaship Model'!C8 | D3: Horizont: | E3: ='Bonaship Model'!C9&" rokov" | F3: Nehnuteľnosť: | G3: ='Bonaship Model'!C6
B5: ① NULA MESAČNÝCH SPLÁTOK — CASHFLOW SLOBODA
B6: Splatnosť | C6: Mes. splátka — Cetelem* | D6: Bonaship — mesačne | E6: Úspora / mesiac | F6: Suma ušetrená za celé obdobie
B7: 3 roky | C7: ='Porovnanie s úvermi'!G12 | D7: 0 | E7: =C7-D7 | F7: =E7*36
B8: 5 rokov | C8: ='Porovnanie s úvermi'!G23 | D8: 0 | E8: =C8-D8 | F8: =E8*60
B9: 7 rokov | C9: ='Porovnanie s úvermi'!G34 | D9: 0 | E9: =C9-D9 | F9: =E9*84
B10: 10 rokov | C10: ='Porovnanie s úvermi'!G45 | D10: 0 | E10: =C10-D10 | F10: =E10*120
B11: *Cetelem – najlacnejší úver na trhu (nebankovka). Bankové inštitúcie = ešte vyššie splátky.
B13: ② CELKOVÉ NÁKLADY FINANCOVANIA
B14: Splatnosť | C14: Náklad (Cetelem) | D14: Bonaship náklad | E14: Rozdiel | F14: Záver
B15: 3 roky | C15: ='Porovnanie s úvermi'!I12 | D15: =('Bonaship Model'!C6*(1+'Bonaship Model'!C10)^3)*'Bonaship Model'!C13+MIN('Bonaship Model'!C8*'Bonaship Model'!C17,'Bonaship Model'!C18)-'Bonaship Model'!C8 | E15: =D15-C15 | F15: =IF(D15<C15,"✅ Bonaship lacnejší","⚠️ Bonaship drahší o "&TEXT(D15-C15,"#,##0 €"))
B16: 5 rokov | C16: ='Porovnanie s úvermi'!I23 | D16: =('Bonaship Model'!C6*(1+'Bonaship Model'!C10)^5)*'Bonaship Model'!C14+MIN('Bonaship Model'!C8*'Bonaship Model'!C17,'Bonaship Model'!C18)-'Bonaship Model'!C8 | E16: =D16-C16 | F16: =IF(D16<C16,"✅ Bonaship lacnejší","⚠️ Bonaship drahší o "&TEXT(D16-C16,"#,##0 €"))
B17: 7 rokov | C17: ='Porovnanie s úvermi'!I34 | D17: =('Bonaship Model'!C6*(1+'Bonaship Model'!C10)^7)*'Bonaship Model'!C15+MIN('Bonaship Model'!C8*'Bonaship Model'!C17,'Bonaship Model'!C18)-'Bonaship Model'!C8 | E17: =D17-C17 | F17: =IF(D17<C17,"✅ Bonaship lacnejší","⚠️ Bonaship drahší o "&TEXT(D17-C17,"#,##0 €"))
B18: 10 rokov | C18: ='Porovnanie s úvermi'!I45 | D18: =('Bonaship Model'!C6*(1+'Bonaship Model'!C10)^10)*'Bonaship Model'!C15+MIN('Bonaship Model'!C8*'Bonaship Model'!C17,'Bonaship Model'!C18)-'Bonaship Model'!C8 | E18: =D18-C18 | F18: =IF(D18<C18,"✅ Bonaship lacnejší","⚠️ Bonaship drahší o "&TEXT(D18-C18,"#,##0 €"))
B19: 📌 Bonaship náklad = poplatok + podiel z predajnej ceny − investovaná suma. Bonaship je drahší v absolútnom vyjadrení, ale zákazník má 0 mesačné splátky a celú sumu okamžite k dispozícii bez nutnosti splácania.
B21: ③ ČISTÁ MAJETKOVÁ POZÍCIA PRI PREDAJI — horizont podľa Model sheetu
B22: Položka | C22: Bonaship | D22: Bankový úver (Cetelem) | E22: Rozdiel
B23: Predajná cena bytu (budúca hodnota) | C23: ='Bonaship Model'!C21 | D23: ='Bonaship Model'!C21 | E23: =C23-D23
B24: − Zostatok hypotéky pri exite | C24: =-'Bonaship Model'!C49 | D24: =-'Bonaship Model'!C49 | E24: =C24-D24
B25: − Bonaship payout (deducted from sale) | C25: =-'Bonaship Model'!C29 | D25: =0 | E25: =C25-D25
B26: =Čistý výnos z predaja bytu | C26: =C23+C24+C25 | D26: =D23+D24+D25 | E26: =C26-D26
B27: Splátky uhradené mesačne počas doby (z vrecka zákazníka) | C27: =0 | D27: =-IF('Bonaship Model'!C9<=3,'Porovnanie s úvermi'!H12,IF('Bonaship Model'!C9<=6,'Porovnanie s úvermi'!H23,IF('Bonaship Model'!C9<=7,'Porovnanie s úvermi'!H34,'Porovnanie s úvermi'!H45))) | E27: =C27-D27
B28: =CELKOVÁ MAJETKOVÁ POZÍCIA | C28: =C26+C27 | D28: =D26+D27 | E28: =C28-D28
B29: 📌 Zelené políčko = zákazník neplatiť nič mesačne. Červené = celkové splátky banke počas doby. Záporný rozdiel v celkovej pozícii = cena za nulové mesačné záväzky.
B30: Zákazník nemusí predávať byt. Môže si zobrať väčší hypotekárny úver (refinancovanie), vybrať nadbytočnú hotovosť a z nej vyplatiť Bonaship. Byt si zachová.
B31: Budúca hodnota bytu | C31: ='Bonaship Model'!C52
B32: Max nová hypotéka (80 % LTV) | C32: ='Bonaship Model'!C53
B33: Zostatok starej hypotéky | C33: ='Bonaship Model'!C54
B34: Dostupná hotovosť (cashout) | C34: ='Bonaship Model'!C55
B35: Bonaship payout (zákazník zaplatí) | C35: ='Bonaship Model'!C56
B36: Zostatok pre zákazníka | C36: ='Bonaship Model'!C57
B37: ✅ Refinancovanie bez predaja možné? | C37: ='Bonaship Model'!C58
B39: ⑤ ĎALŠIE VÝHODY BONASHIP (NEFINANČNÉ)
B40: 💰 Okamžitá likvidita | C40: Zákazník dostane celú sumu ihneď na ruke, bez schvaľovacieho procesu banky
B41: 📅 Žiadne mesačné záväzky | C41: Nula splátok = žiadny finančný stres v náročných mesiacoch (choroba, strata práce)
B42: 📊 Nenarastajúci dlh | C42: Suma pre Bonaship závisí od trhu (cena bytu), nie od úrokového dlhu
B43: 🔓 Flexibilný exit | C43: Zákazník sám rozhoduje: predaj, refinancovanie, odkúpenie podielu — bez sankcií
B44: 🏦 Nezávislé od banky | C44: Neovplyvňuje úverovú históriu, DTI ukazovateľ ani možnosť vziať si hypotéku
B45: 🤝 Zdieľaný záujem | C45: Bonaship má záujem, aby nehnuteľnosť rástla na hodnote — rovnaký cieľ ako zákazník

Sheet Podmienky Bonaship
B2: BONASHIP — Podmienky produktu
B3: Tieto parametre sú prepojené s kalkulačkou na Sheet 1. Editujte tam.
B5: Parameter | C5: Hodnota | D5: Poznámka
B6: Podiel z predajnej ceny (1–3 roky) | C6: ='Bonaship Model'!C13 | D6: % z celkovej predajnej ceny pri exite do 3 rokov
B7: Podiel z predajnej ceny (4–6 rokov) | C7: ='Bonaship Model'!C14 | D7: % z celkovej predajnej ceny pri exite 4–6 rokov
B8: Podiel z predajnej ceny (7–10 rokov) | C8: ='Bonaship Model'!C15 | D8: % z celkovej predajnej ceny pri exite 7–10 rokov
B9: — (zrušené) | C9: N/A | D9: Minimálny výnos sa neuplatňuje — podiel z celkovej hodnoty slúži ako prirodzený floor
B10: Jednorazový poplatok | C10: ='Bonaship Model'!C17 | D10: % z investovanej sumy, odpočítané pri poskytnutí
B11: Max. poplatok | C11: ='Bonaship Model'!C18 | D11: Strop na jednorazový poplatok
B12: Záznam v úverovom registri | C12: NIE | D12: Spolufinancovanie nie je úver → bez záznamu
B13: Mesačné splátky | C13: 0 € | D13: Žiadne priebežné platby investorovi
B14: Vlastníctvo nehnuteľnosti | C14: 100% zákazník | D14: Zákazník je na LV, Bonaship (investor) má len zmluvné právo
B15: Exit — predaj | C15: Áno | D15: Automatické vysporiadanie z výnosu predaja
B16: Exit — refinancovanie | C16: Áno | D16: Navýšenie hypotéky u banky
B17: Exit — vyplatenie z úspor | C17: Áno | D17: Bez pokuty za predčasný exit
B18: Priebežné poplatky | C18: Odhad + právne + kataster | D18: Štandardné náklady, uvedené vopred
